Workbook
Name __bookmark_1: #REF!
Name __bookmark_1: #REF!
Name A: [1]BRACAL!#REF!
Name A: [1]BRACAL!#REF!
Name aA: [2]BRACAL!#REF!
Name aA: [2]BRACAL!#REF!
Name aaa: [2]BRACAL!#REF!
Name aaa: [2]BRACAL!#REF!
Name aaaa: #REF!
Name aaaa: #REF!
Name AB: [1]BRACAL!#REF!
Name AB: [1]BRACAL!#REF!
Name AC: #REF!
Name AC: #REF!
Name aewqeW: #REF!
Name aewqeW: #REF!
Name ajuizatxt: [3]Atualização!#REF!
Name alienacao: #REF!
Name alienacao: #REF!
Name ANALISTA: #REF! tabela9analista
Name ANALISTA: #REF! tabela9analista
Name Apoio: [4]PRJ!$AG$27:$AI$32
Name Área_Construída: #REF!
Name Área_Construída: #REF!
Name as: [2]BRACAL!#REF!
Name as: [2]BRACAL!#REF!
Name asa: [2]BRACAL!#REF!
Name asa: [2]BRACAL!#REF!
Name asd: [2]BRACAL!#REF!
Name asd: [2]BRACAL!#REF!
Name asdf: [2]BRACAL!#REF!
Name asdf: [2]BRACAL!#REF!
Name atualizatxt: [3]Atualização!#REF!
Name b: [1]BRACAL!#REF!
Name ba: [1]BRACAL!#REF!
Name base: #REF!
Name bb: [2]BRACAL!#REF!
Name bb: [2]BRACAL!#REF!
Name bbb: [1]BRACAL!#REF!
Name bbb: [1]BRACAL!#REF!
Name bbbb: [2]BRACAL!#REF!
Name bbbb: [2]BRACAL!#REF!
Name bbbbn: [2]BRACAL!#REF!
Name bbbbn: [2]BRACAL!#REF!
Name bbbn: [1]BRACAL!#REF!
Name bColat: [5]Mult_Exec!$C$12
Name Bem: #REF!
Name Bem: #REF!
Name bm: [2]BRACAL!#REF!
Name bm: [2]BRACAL!#REF!
Name bn: [2]BRACAL!#REF!
Name bn: [2]BRACAL!#REF!
Name C_Node_Total: [6]RECORD!$C$2
Name Chart_Value_Basis: [6]TORNADO!$B$2
Name Cidades: #REF!
Name Cidades: #REF!
Name CN_9_7: #REF!
Name CN_9_7: #REF!
Name CN_9_7_LB_1_Val: #REF!
Name CN_9_7_LB_1_Val: #REF!

Sheet Resumo Imóveis 2 - VENDAS
A1: 72.1
G2: =SUM(G5:G45) -> 21429554 | I2: =SUM(I5:I45) -> 17871567 | V2: =SUM(V5:V45) -> 26936102 | W2: =SUM(W5:W45) -> 19032102
B3: Ativos | F3: Regulatório | G3: Avaliação | AA3: 46092
B4: Mat. | C4: Tipo | D4: Tipologia | E4: Cidade | F4: Registrado? | G4: VF | H4: % Propriedade | I4: VF Líq. | J4: Tem proposta? | K4: Melhor Proposta (ativa) | L4: Comprador | M4: Obs | N4: Carta Adjudicação? | O4: Data Adjudicação | P4: Registro | Q4: Data Registro | R4: SPE | S4: Dt. Avaliação | T4: Valor Avaliação | U4: Valor Venda Forçada | V4: VM Liq | W4: VF Liq | X4: TABELA GI | Y4: Valor recebido / Proposta | Z4: Condições de Venda | AA4: Status atual
B5: 72157 | C5: Urbano | D5: Comercial | E5: Ribeirão Preto/SP | F5: Ok | G5: 1593000 | H5: 1 | I5: 1593000 | J5: - | K5: 3100000 | L5: - | M5: Vendido | N5: SIM | O5: 45917 | P5: Sim | Q5: 45968 | R5: SPE Comercial | S5: 14/08/2025 10:11 | T5: 2969000 | U5: 1781000 | V5: =T5*H5 -> 2969000 | W5: =U5*H5 -> 1781000 | X5: Vendido | Y5: =241607.9+2174471.15 -> 2416079 | Z5: Pago | AA5: Vendido
B6: 62872 | C6: Urbano | D6: Comercial | E6: Ribeirão Preto/SP | F6: Ok | G6: 533549 | H6: 1 | I6: 533549 | J6: - | K6: - | L6: - | M6: Vendido (em conjunto 62872 e 72157) | N6: SIM | O6: 45917 | P6: Sim | Q6: 45968 | R6: SPE Comercial | S6: 14/08/2025 10:16 | T6: 1002000 | U6: 701000 | V6: =T6*H6 -> 1002000 | W6: =U6*H6 -> 701000 | X6: Vendido | Y6: =68392.1+615528.85 -> 683920.95 | Z6: Pago | AA6: Vendido
B7: 83398 | C7: Urbano | D7: Comercial | E7: Ribeirão Preto/SP | F7: Ok | G7: 710900 | H7: 0.5 | I7: 355450 | J7: - | K7: - | L7: - | M7: - | N7: SIM | O7: 45834 | P7: Sim | Q7: 45968 | R7: SPE Comercial | S7: 19/08/2025 15:25 | T7: 643000 | U7: 457000 | V7: =T7*H7 -> 321500 | W7: =U7*H7 -> 228500 | X7: Vendido | Y7: 250000 | Z7: Pago | AA7: Vendido
B8: 23299 | C8: Urbano | D8: Comercial | E8: Ribeirão Preto/SP | F8: Ok | G8: 3833000 | H8: 1 | I8: 3833000 | J8: - | K8: - | L8: - | M8: - | N8: SIM | O8: 45834 | P8: Sim | Q8: 45925 | R8: SPE Comercial | S8: 14/08/2025 10:07 | T8: 7158000 | U8: 4796000 | V8: =T8*H8 -> 7158000 | W8: =U8*H8 -> 4796000 | X8: 6000000 | Y8: 6150000 | Z8: A vista | AA8: Aprovado - em escritura | AB8: vendido??
B9: 48207 | C9: Urbano | D9: Residencial | E9: Ribeirão Preto/SP | F9: Ok | G9: 2217000 | H9: 1 | I9: 2217000 | J9: - | K9: - | L9: - | M9: - | N9: SIM | O9: 45834 | P9: Sim | Q9: 45898 | R9: SPE Residencial | S9: 07/10/2025 17:44 | T9: 3074000 | U9: 2460000 | V9: =T9*H9 -> 3074000 | W9: =U9*H9 -> 2460000 | X9: 6000000 | Y9: - | Z9: - | AA9: Sem proposta | AF9: 1621
B10: 32744 | C10: Urbano | D10: Residencial | E10: Ribeirão Preto/SP | F10: Ok | G10: 980000 | H10: 1 | I10: 980000 | J10: - | K10: - | L10: - | M10: - | N10: SIM | O10: 45917 | P10: Sim | Q10: 46009 | R10: SPE Residencial | S10: 17/07/2025 17:22 | T10: 2741000 | U10: 1645000 | V10: =T10*H10 -> 2741000 | W10: =U10*H10 -> 1645000 | X10: 2750000 | Y10: - | Z10: - | AA10: Sem proposta | AF10: =11%*AF9 -> 178.31
B11: 5104 | C11: Urbano | D11: Comercial | E11: Ribeirão Preto/SP | F11: Ok | G11: 727000 | H11: 1 | I11: 727000 | J11: - | K11: - | L11: - | M11: - | N11: SIM | O11: 45917 | P11: Sim | Q11: 45971 | R11: SPE Comercial | S11: 19/12/2025 09:30 | T11: 1003000 | U11: 732000 | V11: =T11*H11 -> 1003000 | W11: =U11*H11 -> 732000 | X11: 1024000 | Y11: - | Z11: - | AA11: Sem proposta
B12: 76858 | C12: Urbano | D12: Comercial | E12: Ribeirão Preto/SP | F12: Ok | G12: 590500 | H12: 1 | I12: 590500 | J12: - | K12: - | L12: - | M12: - | N12: SIM | O12: 45834 | P12: Sim | Q12: 45916 | R12: SPE Comercial | S12: 08/07/2025 15:09 | T12: 672000 | U12: 470000 | V12: =T12*H12 -> 672000 | W12: =U12*H12 -> 470000 | X12: 672000 | Y12: - | Z12: - | AA12: Sem proposta
B13: 3417 | C13: Urbano | D13: Residencial | E13: Ribeirão Preto/SP | F13: Ok | G13: 462000 | H13: 1 | I13: 462000 | J13: - | K13: - | L13: - | M13: - | N13: SIM | O13: 45834 | P13: Sim | Q13: 46009 | R13: SPE Residencial | S13: 10/07/2025 11:07 | T13: 579000 | U13: 446000 | V13: =T13*H13 -> 579000 | W13: =U13*H13 -> 446000 | X13: 636900 | Y13: - | Z13: - | AA13: Sem proposta
B14: 5103 | C14: Urbano | D14: Comercial | E14: Ribeirão Preto/SP | F14: Ok | G14: 439000 | H14: 1 | I14: 439000 | J14: - | K14: - | L14: - | M14: - | N14: SIM | O14: 45917 | P14: Sim | Q14: 46008 | R14: SPE Comercial | S14: 13/01/2026 12:45 | T14: 536000 | U14: 391000 | V14: =T14*H14 -> 536000 | W14: =U14*H14 -> 391000 | X14: 571000 | Y14: - | Z14: - | AA14: Sem proposta
B15: 52218 | C15: Urbano | D15: Residencial | E15: Ribeirão Preto/SP | F15: Ok | G15: 436000 | H15: 1 | I15: 436000 | J15: - | K15: - | L15: - | M15: - | N15: SIM | O15: 45917 | P15: Sim | Q15: 46009 | R15: SPE Residencial | S15: 17/07/2025 17:27 | T15: 656000 | U15: 459000 | V15: =T15*H15 -> 656000 | W15: =U15*H15 -> 459000 | X15: 656000 | Y15: - | Z15: - | AA15: Sem proposta
B16: 149 | C16: Urbano | D16: Residencial | E16: Ribeirão Preto/SP | F16: Ok | G16: 311000 | H16: 0.33333333 | I16: 103666.67 | J16: - | K16: - | L16: - | M16: - | N16: SIM | O16: 45834 | P16: Sim | Q16: 46003 | R16: SPE Residencial | S16: 18/07/2025 09:51 | T16: 297000 | U16: 228000 | V16: =T16*H16 -> 99000 | W16: =U16*H16 -> 76000 | X16: 108900 | Y16: - | Z16: - | AA16: Sem proposta
B17: 78782 | C17: Urbano | D17: Residencial | E17: Ribeirão Preto/SP | F17: Ok | G17: 221000 | H17: 1 | I17: 221000 | J17: - | K17: - | L17: - | M17: - | N17: SIM | O17: 45834 | P17: Sim | Q17: 45940 | R17: SPE Residencial | S17: 13/01/2026 12:47 | T17: 308000 | U17: 237000 | V17: =T17*H17 -> 308000 | W17: =U17*H17 -> 237000 | X17: 180000 | Y17: - | Z17: - | AA17: Sem proposta
B18: 59250 | C18: Urbano | D18: Residencial | E18: Ribeirão Preto/SP | F18: Ok | G18: 160000 | H18: 1 | I18: 160000 | J18: - | K18: - | L18: - | M18: - | N18: SIM | O18: 45834 | P18: Sim | Q18: 45968 | R18: SPE Residencial | S18: 19/11/2025 10:09 | T18: 232000 | U18: 165000 | V18: =T18*H18 -> 232000 | W18: =U18*H18 -> 165000 | X18: 190000 | Y18: - | Z18: - | AA18: Sem proposta
B19: 78780 | C19: Urbano | D19: Residencial | E19: Ribeirão Preto/SP | F19: Ok | G19: 154000 | H19: 1 | I19: 154000 | J19: - | K19: - | L19: - | M19: - | N19: SIM | O19: 45834 | P19: Sim | Q19: 45898 | R19: SPE Residencial | S19: 08/07/2025 14:00 | T19: 184000 | U19: 142000 | V19: =T19*H19 -> 184000 | W19: =U19*H19 -> 142000 | X19: 180000 | Y19: - | Z19: - | AA19: Sem proposta
B20: 78781 | C20: Urbano | D20: Residencial | E20: Ribeirão Preto/SP | F20: Ok | G20: 154000 | H20: 1 | I20: 154000 | J20: - | K20: - | L20: - | M20: - | N20: SIM | O20: 45834 | P20: Sim | Q20: 45898 | R20: SPE Residencial | S20: 10/07/2025 10:59 | T20: 184000 | U20: 141000 | V20: =T20*H20 -> 184000 | W20: =U20*H20 -> 141000 | X20: 180000 | Y20: - | Z20: - | AA20: Sem proposta
B21: 78783 | C21: Urbano | D21: Residencial | E21: Ribeirão Preto/SP | F21: Ok | G21: 154000 | H21: 1 | I21: 154000 | J21: - | K21: - | L21: - | M21: - | N21: SIM | O21: 45834 | P21: Sim | Q21: 45898 | R21: SPE Residencial | S21: 08/07/2025 14:21 | T21: 184000 | U21: 142000 | V21: =T21*H21 -> 184000 | W21: =U21*H21 -> 142000 | X21: 180000 | Y21: - | Z21: - | AA21: Sem proposta
B22: 78784 | C22: Urbano | D22: Residencial | E22: Ribeirão Preto/SP | F22: Ok | G22: 154000 | H22: 1 | I22: 154000 | J22: - | K22: - | L22: - | M22: - | N22: SIM | O22: 45834 | P22: Sim | Q22: 45898 | R22: SPE Residencial | S22: 08/07/2025 14:24 | T22: 184000 | U22: 142000 | V22: =T22*H22 -> 184000 | W22: =U22*H22 -> 142000 | X22: 180000 | Y22: - | Z22: - | AA22: Sem proposta
... B29: 102754 | C29: Urbano | D29: Residencial | E29: Ribeirão Preto/SP | F29: Ok | G29: 136000 | H29: 1 | I29: 136000 | J29: - | K29: - | L29: - | M29: - | N29: SIM | O29: 45834 | P29: Sim | Q29: 45971 | R29: SPE Residencial | S29: 08/10/2025 10:16 | T29: 168000 | U29: 118000 | V29: =T29*H29 -> 168000 | W29: =U29*H29 -> 118000 | X29: 180000 | Y29: - | Z29: - | AA29: Sem proposta
B30: 36052 | C30: Urbano | D30: Comercial | E30: Ribeirão Preto/SP | F30: Ok | G30: 123000 | H30: 1 | I30: 123000 | J30: - | K30: - | L30: - | M30: - | N30: NÃO | O30: - | P30: Não | Q30: - | R30: SPE Comercial | S30: 16/01/2026 18:15 | T30: 159000 | U30: 122000 | V30: =T30*H30 -> 159000 | W30: =U30*H30 -> 122000 | X30: 165000 | Y30: - | Z30: - | AA30: Sem proposta
B31: 36053 | C31: Urbano | D31: Comercial | E31: Ribeirão Preto/SP | F31: Ok | G31: 123000 | H31: 1 | I31: 123000 | J31: - | K31: - | L31: - | M31: - | N31: NÃO | O31: - | P31: Não | Q31: - | R31: SPE Comercial | S31: 13/01/2026 12:49 | T31: 137000 | U31: 105000 | V31: =T31*H31 -> 137000 | W31: =U31*H31 -> 105000 | X31: 165000 | Y31: - | Z31: - | AA31: Sem proposta
B32: 96154 | C32: Urbano | D32: Residencial | E32: Ribeirão Preto/SP | F32: Ok | G32: 109000 | H32: 1 | I32: 109000 | J32: - | K32: - | L32: - | M32: - | N32: SIM | O32: 45834 | P32: Sim | Q32: 45915 | R32: SPE Residencial | S32: 10/07/2025 10:48 | T32: 187000 | U32: 131000 | V32: =T32*H32 -> 187000 | W32: =U32*H32 -> 131000 | X32: 169760 | Y32: - | Z32: - | AA32: Sem proposta
B33: 96155 | C33: Urbano | D33: Residencial | E33: Ribeirão Preto/SP | F33: Ok | G33: 109000 | H33: 1 | I33: 109000 | J33: - | K33: - | L33: - | M33: - | N33: SIM | O33: 45834 | P33: Sim | Q33: 45915 | R33: SPE Residencial | S33: 10/07/2025 10:46 | T33: 187000 | U33: 131000 | V33: =T33*H33 -> 187000 | W33: =U33*H33 -> 131000 | X33: 169760 | Y33: - | Z33: - | AA33: Sem proposta
B34: 96157 | C34: Urbano | D34: Residencial | E34: Ribeirão Preto/SP | F34: Ok | G34: 62000 | H34: 1 | I34: 62000 | J34: - | K34: - | L34: - | M34: - | N34: SIM | O34: 45834 | P34: Sim | Q34: 45915 | R34: SPE Residencial | S34: 10/07/2025 17:48 | T34: 101000 | U34: 65000 | V34: =T34*H34 -> 101000 | W34: =U34*H34 -> 65000 | X34: 138240 | Y34: - | Z34: - | AA34: Sem proposta
B35: 96156 | C35: Urbano | D35: Residencial | E35: Ribeirão Preto/SP | F35: Ok | G35: 62000 | H35: 1 | I35: 62000 | J35: - | K35: - | L35: - | M35: - | N35: SIM | O35: 45834 | P35: Sim | Q35: 45915 | R35: SPE Residencial | S35: 14/07/2025 22:16 | T35: 101000 | U35: 65000 | V35: =T35*H35 -> 101000 | W35: =U35*H35 -> 65000 | X35: 138240 | Y35: - | Z35: - | AA35: Sem proposta
B36: 96158 | C36: Urbano | D36: Comercial | E36: Ribeirão Preto/SP | F36: Ok | G36: 127800 | H36: 1 | I36: 127800 | J36: - | K36: - | L36: - | M36: - | N36: SIM | O36: 45834 | P36: Sim | Q36: 45915 | R36: SPE Comercial | S36: 10/07/2025 11:16 | T36: 144000 | U36: 101000 | V36: =T36*H36 -> 144000 | W36: =U36*H36 -> 101000 | X36: 158400 | Y36: - | Z36: - | AA36: Sem proposta
B37: 116945 | C37: Urbano | D37: Residencial | E37: Ilha Comprida/SP | F37: Ok | G37: 0 | H37: 1 | I37: 0 | J37: - | K37: - | L37: - | M37: - | N37: SIM | O37: 45834 | P37: Sim | Q37: 45902 | R37: SPE Residencial | S37: 21/10/2025 09:53 | T37: 15000 | U37: 0 | V37: =T37*H37 -> 15000 | W37: =U37*H37 -> 0 | X37: 15000 | Y37: - | Z37: - | AA37: Sem proposta
B38: 116946 | C38: Urbano | D38: Residencial | E38: Ilha Comprida/SP | F38: Ok | G38: 0 | H38: 1 | I38: 0 | J38: - | K38: - | L38: - | M38: - | N38: SIM | O38: 45834 | P38: Sim | Q38: 45902 | R38: SPE Residencial | S38: 21/10/2025 09:54 | T38: 15000 | U38: 0 | V38: =T38*H38 -> 15000 | W38: =U38*H38 -> 0 | X38: 15000 | Y38: - | Z38: - | AA38: Sem proposta
B39: 6660 | C39: Urbano | D39: Comercial | E39: Ribeirão Preto/SP | F39: Ok | G39: 1923389.1 | H39: 0.33333333 | I39: 641129.69 | J39: - | K39: - | L39: - | M39: - | N39: SIM | O39: 45834 | P39: Sim | Q39: 46010 | R39: SPE Comercial | S39: 17/10/2023 12:01 | T39: 1923389.1 | U39: 1923389.1 | V39: =T39*H39 -> 641129.69 | W39: =U39*H39 -> 641129.69 | X39: Bloqueado para time comercial | Y39: - | Z39: - | AA39: n/a
B40: 11055 | C40: Urbano | D40: Comercial | E40: Ribeirão Preto/SP | F40: Ok | G40: 1832137.3 | H40: 0.33333333 | I40: 610712.44 | J40: - | K40: - | L40: - | M40: - | N40: SIM | O40: 45834 | P40: Sim | Q40: 46003 | R40: SPE Comercial | S40: 17/10/2023 11:55 | T40: 1832137.3 | U40: 1832137.3 | V40: =T40*H40 -> 610712.44 | W40: =U40*H40 -> 610712.44 | X40: Bloqueado para time comercial | Y40: - | Z40: - | AA40: n/a
B41: 11054 | C41: Urbano | D41: Comercial | E41: Ribeirão Preto/SP | F41: Ok | G41: 737278.6 | H41: 0.33333333 | I41: 245759.53 | J41: - | K41: - | L41: - | M41: - | N41: SIM | O41: 45834 | P41: Sim | Q41: 46003 | R41: SPE Comercial | S41: 17/10/2023 12:09 | T41: 737278.6 | U41: 737278.6 | V41: =T41*H41 -> 245759.53 | W41: =U41*H41 -> 245759.53 | X41: Bloqueado para time comercial | Y41: - | Z41: - | AA41: n/a
B42: 6529 | C42: Urbano | D42: Residencial | E42: Ribeirão Preto/SP | F42: Ok | G42: 230000 | H42: 1 | I42: 230000 | J42: - | K42: - | L42: - | M42: - | N42: SIM | O42: 45834 | P42: Sim | Q42: 45898 | R42: SPE Residencial | S42: 07/10/2025 10:19 | T42: 418000 | U42: 293000 | V42: =T42*H42 -> 418000 | W42: =U42*H42 -> 293000 | X42: Bloqueado para time comercial | Y42: - | Z42: - | AA42: n/a
B43: 53194 | C43: Urbano | D43: Residencial | E43: Ribeirão Preto/SP | F43: Ok | G43: 222000 | H43: 1 | I43: 222000 | J43: - | K43: - | L43: - | M43: - | N43: SIM | O43: 45834 | P43: Sim | Q43: 45898 | R43: SPE Residencial | S43: 07/10/2025 10:18 | T43: 414000 | U43: 290000 | V43: =T43*H43 -> 414000 | W43: =U43*H43 -> 290000 | X43: Bloqueado para time comercial | Y43: - | Z43: - | AA43: n/a
B44: 6549 | C44: Urbano | D44: Residencial | E44: Ribeirão Preto/SP | F44: Ok | G44: 822000 | H44: 1 | I44: 822000 | J44: - | K44: - | L44: - | M44: - | N44: SIM | O44: 45834 | P44: Sim | Q44: 46010 | R44: SPE Residencial | S44: 17/07/2025 17:13 | T44: 0 | U44: 0 | V44: =T44*H44 -> 0 | W44: =U44*H44 -> 0 | X44: Bloqueado para time comercial | Y44: - | Z44: - | AA44: n/a
B45: 96153 | C45: Urbano | D45: Residencial | E45: Ribeirão Preto/SP | F45: Ok | G45: 109000 | H45: 1 | I45: 109000 | J45: - | K45: - | L45: - | M45: - | N45: SIM | O45: 45834 | P45: Não | Q45: - | R45: SPE Residencial | S45: 10/07/2025 10:44 | T45: 187000 | U45: 131000 | V45: =T45*H45 -> 187000 | W45: =U45*H45 -> 131000 | X45: Bloqueado para time comercial | Y45: - | Z45: - | AA45: n/a
G46: =SUM(G5:G45) -> 21429554 | I46: =SUM(I5:I45) -> 17871567 | K46: =SUM(K5:K45) -> 3100000

Sheet Pgto Alugueis Processo
B2: Mat. | C2: Data | D2: Mês Aluguel | E2: Dt Adjudicação | F2: Valor Depositado | H2: Apto
B3: 78783 | C3: 45923 | D3: junho | E3: 45834 | F3: 306.38 | H3: 22
B4: 78783 | C4: 45923 | D4: julho | E4: 45834 | F4: 276.46 | H4: 22
B5: 78783 | C5: 45923 | D5: agosto | E5: 45834 | F5: 52.35 | H5: 22
B6: 78783 | C6: 45923 | D6: setembro | E6: 45834 | F6: 14.95 | H6: 22
B7: 78785 | C7: 45923 | D7: junho | E7: 45834 | F7: 973.31 | H7: 32
B8: 78785 | C8: 45923 | D8: julho | E8: 45834 | F8: 973.31 | H8: 32
B9: 78785 | C9: 45923 | D9: agosto | E9: 45834 | F9: 973.31 | H9: 32
B10: 78785 | C10: 45923 | D10: setembro | E10: 45834 | F10: 973.31 | H10: 32
B11: 78786 | C11: 45923 | D11: junho | E11: 45834 | F11: 2015.69 | H11: 41
B12: 78786 | C12: 45923 | D12: agosto | E12: 45834 | F12: 949.77 | H12: 41
B13: 78787 | C13: 45923 | D13: junho | E13: 45834 | F13: 827.87 | H13: 42
B14: 78787 | C14: 45923 | D14: julho | E14: 45834 | F14: 827.87 | H14: 42
... B16: 78787 | C16: 45923 | D16: setembro | E16: 45834 | F16: 827.87 | H16: 42
B17: TOTAL | F17: =SUM(F3:F16) -> 10470.32

Sheet Pgto Alugueis SPE RESIDENCIAL
B2: Valor | C2: Data Recebimento | D2: Imóvel
B3: 973.31 | C3: 45973 | D3: 3039
B4: 851.3 | C4: 45978 | D4: 3026
B5: 577.87 | C5: 45982 | D5: 3150
B6: 1065.92 | C6: 45986 | D6: 3012
B7: 956.09 | C7: 45987 | D7: 3367
B8: 973.31 | C8: 46002 | D8: 3039
B9: 851.3 | C9: 46009 | D9: 3026
B10: 827.27 | C10: 46380 | D10: 3150
B11: 956.09 | C11: 46020 | D11: 3367
B12: 975.8 | C12: 46035 | D12: 3039
B13: 853.8 | C13: 46041 | D13: 3026
B14: 1419.51 | C14: 46048 | D14: 3150
... B18: 3808.24 | C18: 45965 | D18: 3012

Sheet Resumo Imóveis
M2: EM REVISÃO
L3: =SUM(L5:L45) -> 23939000 | M3: =SUM(M5:M45) -> 21429554 | O3: =SUM(O5:O45) -> 17871567
B4: Origem | C4: Matrícula | D4: Carta Adjudicação | E4: Procuradoria | F4: Classe Imóvel | G4: Tipologia | H4: Cartório | I4: Cidade | J4: Dt. Avaliação | K4: Nível | L4: Valor FCC | M4: VF | N4: % Propriedade | O4: VF Líq. | R4: DECISÃO 26/06/2025
A5: Previsão 08/10 | B5: FCC | C5: 23299 | D5: 1 | E5: =IFERROR(VLOOKUP(C5,$U$22:$U$27,1,0),"-") -> - | F5: Imóvel Urbano | G5: Comercial | H5: 2º CRI | I5: Ribeirão Preto/SP | J5: 45189.369 | K5: Nível 2 | L5: =VLOOKUP(C5,[14]Planilha1!M:N,2,0) -> 6683000 | M5: 3833000 | N5: 1 | O5: =N5*M5 -> 3833000
A6: Registrado | B6: FCC | C6: 48207 | D6: 1 | E6: =IFERROR(VLOOKUP(C6,$U$22:$U$27,1,0),"-") -> - | F6: Imóvel Urbano | G6: Residencial | H6: 2º CRI | I6: Ribeirão Preto/SP | J6: 45804.5 | K6: Nível 3 | L6: =VLOOKUP(C6,[14]Planilha1!M:N,2,0) -> 2725000 | M6: 2217000 | N6: 1 | O6: =N6*M6 -> 2217000
A7: Previsão 05/09 | B7: FCC | C7: 6660 | D7: 1 | E7: =IFERROR(VLOOKUP(C7,$U$22:$U$27,1,0),"-") -> - | F7: Imóvel Urbano | G7: Comercial | H7: 2º CRI | I7: Ribeirão Preto/SP | J7: 45211.867 | K7: Nível 3 | L7: =VLOOKUP(C7,[14]Planilha1!M:N,2,0) -> 4316000 | M7: 1923389.1 | N7: 0.33333333 | O7: =N7*M7 -> 641129.69
A8: Previsão 05/09 | B8: FCC | C8: 11055 | D8: 1 | E8: =IFERROR(VLOOKUP(C8,$U$22:$U$27,1,0),"-") -> - | F8: Imóvel Urbano | G8: Comercial | H8: 2º CRI | I8: Ribeirão Preto/SP | J8: 45211.867 | K8: Nível 3 | L8: =VLOOKUP(C8,[14]Planilha1!M:N,2,0) -> 0 | M8: 1832137.3 | N8: 0.33333333 | O8: =N8*M8 -> 610712.44 | U8: 33/41
A9: Previsão 05/09 | B9: FCC | C9: 11054 | D9: 1 | E9: =IFERROR(VLOOKUP(C9,$U$22:$U$27,1,0),"-") -> - | F9: Imóvel Urbano | G9: Comercial | H9: 2º CRI | I9: Ribeirão Preto/SP | J9: 45211.867 | K9: Nível 3 | L9: =VLOOKUP(C9,[14]Planilha1!M:N,2,0) -> 0 | M9: 737278.6 | N9: 0.33333333 | O9: =N9*M9 -> 245759.53
A10: Sem Carta | B10: FCC | C10: 72157 | D10: - | E10: 1 | F10: Imóvel Urbano | G10: Comercial | H10: 2º CRI | I10: Ribeirão Preto/SP | J10: 45190.7 | K10: Nível 3 | L10: =VLOOKUP(C10,[14]Planilha1!M:N,2,0) -> 1704000 | M10: 1593000 | N10: 1 | O10: =N10*M10 -> 1593000 | P10: vendido | R10: ENF SPE COMERCIAL LTDA
A11: Sem Carta | B11: FCC | C11: 32744 | D11: - | E11: 1 | F11: Imóvel Urbano | G11: Residencial | H11: 1º CRI | I11: Ribeirão Preto/SP | J11: 45117.595 | K11: Nível 2 | L11: =VLOOKUP(C11,[14]Planilha1!M:N,2,0) -> 1026000 | M11: 980000 | N11: 1 | O11: =N11*M11 -> 980000 | R11: 23299 | S11: 3833000 | U11: Tipologia | V11: Total | W11: Liberado | X11: %
A12: Sem Carta | B12: FCC | C12: 5104 | D12: - | E12: 1 | F12: Imóvel Urbano | G12: Comercial | H12: 1º CRI | I12: Ribeirão Preto/SP | J12: 45117.623 | K12: Nível 2 | L12: =VLOOKUP(C12,[14]Planilha1!M:N,2,0) -> 717000 | M12: 727000 | N12: 1 | O12: =N12*M12 -> 727000 | R12: 6660 | S12: 641129.69 | U12: Comercial | V12: =SUMIF($G$4:$G$45,U12,$O$4:$O$45) -> 9942900.7 | W12: =S18 -> 6404351.7 | X12: =W12/V12 -> 0.64411301
A13: Previsão 03/10 | B13: FCC | C13: 76858 | D13: 1 | E13: =IFERROR(VLOOKUP(C13,$U$22:$U$27,1,0),"-") -> - | F13: Imóvel Urbano | G13: Comercial | H13: 1º CRI | I13: Ribeirão Preto/SP | J13: 45222.679 | K13: Nível 2 | L13: =VLOOKUP(C13,[14]Planilha1!M:N,2,0) -> 778000 | M13: 590500 | N13: 1 | O13: =N13*M13 -> 590500 | R13: 11055 | S13: 610712.44 | U13: Residencial | V13: =SUMIF($G$4:$G$45,U13,$O$4:$O$45) -> 7928666.7 | W13: =S48 -> 6512666.7 | X13: =W13/V13 -> 0.82140755
A14: Sem Carta | B14: FCC | C14: 62872 | D14: - | E14: 1 | F14: Imóvel Urbano | G14: Comercial | H14: 2º CRI | I14: Ribeirão Preto/SP | J14: 45190.675 | K14: Nível 3 | L14: =VLOOKUP(C14,[14]Planilha1!M:N,2,0) -> 501000 | M14: 533549 | N14: 1 | O14: =N14*M14 -> 533549 | P14: vendido | R14: 11054 | S14: 245759.53 | U14: Total | V14: =SUM(V12:V13) -> 17871567 | W14: =SUM(W12:W13) -> 12917018 | X14: =W14/V14 -> 0.72276919
A15: Previsão 29/09 | B15: FCC | C15: 3417 | D15: 1 | E15: =IFERROR(VLOOKUP(C15,$U$22:$U$27,1,0),"-") -> - | F15: Imóvel Urbano | G15: Residencial | H15: 1º CRI | I15: Ribeirão Preto/SP | J15: 45219.681 | K15: Nível 2 | L15: =VLOOKUP(C15,[14]Planilha1!M:N,2,0) -> 835000 | M15: 462000 | N15: 1 | O15: =N15*M15 -> 462000 | R15: 83398 | S15: 355450
A16: Sem Carta | B16: FCC | C16: 5103 | D16: - | E16: 1 | F16: Imóvel Urbano | G16: Comercial | H16: 1º CRI | I16: Ribeirão Preto/SP | J16: 45219.687 | K16: Nível 2 | L16: =VLOOKUP(C16,[14]Planilha1!M:N,2,0) -> 637000 | M16: 439000 | N16: 1 | O16: =N16*M16 -> 439000 | R16: 76858 | S16: 590500 | V16: =V14-W14 -> 4954549
A17: Sem Carta | B17: FCC | C17: 52218 | D17: - | E17: 1 | F17: Imóvel Urbano | G17: Residencial | H17: 2º CRI | I17: Ribeirão Preto/SP | J17: 45219.716 | K17: Nível 2 | L17: =VLOOKUP(C17,[14]Planilha1!M:N,2,0) -> 608000 | M17: 436000 | N17: 1 | O17: =N17*M17 -> 436000 | R17: 96158 | S17: 127800
A18: Previsão 26/09 | B18: FCC | C18: 149 | D18: 1 | E18: =IFERROR(VLOOKUP(C18,$U$22:$U$27,1,0),"-") -> - | F18: Imóvel Urbano | G18: Residencial | H18: 2º CRI | I18: Ribeirão Preto/SP | J18: 45219.675 | K18: Nível 2 | L18: =VLOOKUP(C18,[14]Planilha1!M:N,2,0) -> 322000 | M18: 311000 | N18: 0.33333333 | O18: =N18*M18 -> 103666.67 | R18: 7 | S18: 6404351.7
A19: Registrado | B19: FCC | C19: 6529 | D19: 1 | E19: =IFERROR(VLOOKUP(C19,$U$22:$U$27,1,0),"-") -> - | F19: Imóvel Urbano | G19: Residencial | H19: 2º CRI | I19: Ribeirão Preto/SP | J19: 45219.694 | K19: Nível 2 | L19: =VLOOKUP(C19,[14]Planilha1!M:N,2,0) -> 269000 | M19: 230000 | N19: 1 | O19: =N19*M19 -> 230000
A20: Registrado | B20: FCC | C20: 53194 | D20: 1 | E20: =IFERROR(VLOOKUP(C20,$U$22:$U$27,1,0),"-") -> - | F20: Imóvel Urbano | G20: Residencial | H20: 2º CRI | I20: Ribeirão Preto/SP | J20: 45219.722 | K20: Nível 2 | L20: =VLOOKUP(C20,[14]Planilha1!M:N,2,0) -> 265000 | M20: 222000 | N20: 1 | O20: =N20*M20 -> 222000
A21: Previsão 26/09 | B21: FCC | C21: 78782 | D21: 1 | E21: =IFERROR(VLOOKUP(C21,$U$22:$U$27,1,0),"-") -> - | F21: Imóvel Urbano | G21: Residencial | H21: 2º CRI | I21: Ribeirão Preto/SP | J21: 45106.478 | K21: Nível 2 | L21: =VLOOKUP(C21,[14]Planilha1!M:N,2,0) -> 177625 | M21: 221000 | N21: 1 | O21: =N21*M21 -> 221000 | R21: ENF SPE RESIDENCIAL LTDA | U21: PROCURADORIA | W21: CONDOMÍNIO
A22: Previsão 26/09 | B22: FCC | C22: 59250 | D22: 1 | E22: =IFERROR(VLOOKUP(C22,$U$22:$U$27,1,0),"-") -> - | F22: Imóvel Urbano | G22: Residencial | H22: 2º CRI | I22: Ribeirão Preto/SP | J22: 45219.672 | K22: Nível 2 | L22: =VLOOKUP(C22,[14]Planilha1!M:N,2,0) -> 247000 | M22: 160000 | N22: 1 | O22: =N22*M22 -> 160000 | R22: 48207 | S22: 2217000 | U22: 5104 | V22: =VLOOKUP(U22,$C:$P,13,0) -> 727000 | W22: 36052 | X22: =VLOOKUP(W22,$C:$P,13,0) -> 123000
A23: Registrado | B23: FCC | C23: 78780 | D23: 1 | E23: =IFERROR(VLOOKUP(C23,$U$22:$U$27,1,0),"-") -> - | F23: Imóvel Urbano | G23: Residencial | H23: 2º CRI | I23: Ribeirão Preto/SP | J23: 45219.736 | K23: Nível 2 | L23: =VLOOKUP(C23,[14]Planilha1!M:N,2,0) -> 177625 | M23: 154000 | N23: 1 | O23: =N23*M23 -> 154000 | R23: 6529 | S23: 230000 | U23: 5103 | V23: =VLOOKUP(U23,$C:$P,13,0) -> 439000 | W23: 36053 | X23: =VLOOKUP(W23,$C:$P,13,0) -> 123000
A24: Registrado | B24: FCC | C24: 78781 | D24: 1 | E24: =IFERROR(VLOOKUP(C24,$U$22:$U$27,1,0),"-") -> - | F24: Imóvel Urbano | G24: Residencial | H24: 2º CRI | I24: Ribeirão Preto/SP | J24: 45219.736 | K24: Nível 2 | L24: =VLOOKUP(C24,[14]Planilha1!M:N,2,0) -> 177625 | M24: 154000 | N24: 1 | O24: =N24*M24 -> 154000 | R24: 6549 | S24: 822000 | U24: 52218 | V24: =VLOOKUP(U24,$C:$P,13,0) -> 436000 | X24: =SUM(X22:X23) -> 246000
A25: Registrado | B25: FCC | C25: 78783 | D25: 1 | E25: =IFERROR(VLOOKUP(C25,$U$22:$U$27,1,0),"-") -> - | F25: Imóvel Urbano | G25: Residencial | H25: 2º CRI | I25: Ribeirão Preto/SP | J25: 45219.736 | K25: Nível 2 | L25: =VLOOKUP(C25,[14]Planilha1!M:N,2,0) -> 177625 | M25: 154000 | N25: 1 | O25: =N25*M25 -> 154000 | R25: 3417 | S25: 462000 | U25: 72157 | V25: =VLOOKUP(U25,$C:$P,13,0) -> 1593000
A26: Registrado | B26: FCC | C26: 78784 | D26: 1 | E26: =IFERROR(VLOOKUP(C26,$U$22:$U$27,1,0),"-") -> - | F26: Imóvel Urbano | G26: Residencial | H26: 2º CRI | I26: Ribeirão Preto/SP | J26: 45219.736 | K26: Nível 2 | L26: =VLOOKUP(C26,[14]Planilha1!M:N,2,0) -> 177625 | M26: 154000 | N26: 1 | O26: =N26*M26 -> 154000 | R26: 149 | S26: 103666.67 | U26: 62872 | V26: =VLOOKUP(U26,$C:$P,13,0) -> 533549
A27: Registrado | B27: FCC | C27: 78785 | D27: 1 | E27: =IFERROR(VLOOKUP(C27,$U$22:$U$27,1,0),"-") -> - | F27: Imóvel Urbano | G27: Residencial | H27: 2º CRI | I27: Ribeirão Preto/SP | J27: 45219.736 | K27: Nível 2 | L27: =VLOOKUP(C27,[14]Planilha1!M:N,2,0) -> 177625 | M27: 154000 | N27: 1 | O27: =N27*M27 -> 154000 | R27: 53194 | S27: 222000 | U27: 32744 | V27: =VLOOKUP(U27,$C:$P,13,0) -> 980000
A28: Registrado | B28: FCC | C28: 78786 | D28: 1 | E28: =IFERROR(VLOOKUP(C28,$U$22:$U$27,1,0),"-") -> - | F28: Imóvel Urbano | G28: Residencial | H28: 2º CRI | I28: Ribeirão Preto/SP | J28: 45219.737 | K28: Nível 2 | L28: =VLOOKUP(C28,[14]Planilha1!M:N,2,0) -> 177625 | M28: 154000 | N28: 1 | O28: =N28*M28 -> 154000 | R28: 78782 | S28: 221000 | V28: =SUM(V22:V27) -> 4708549
A29: Registrado | B29: FCC | C29: 78787 | D29: 1 | E29: =IFERROR(VLOOKUP(C29,$U$22:$U$27,1,0),"-") -> - | F29: Imóvel Urbano | G29: Residencial | H29: 2º CRI | I29: Ribeirão Preto/SP | J29: 45219.737 | K29: Nível 2 | L29: =VLOOKUP(C29,[14]Planilha1!M:N,2,0) -> 177625 | M29: 154000 | N29: 1 | O29: =N29*M29 -> 154000 | R29: 59250 | S29: 160000
A30: Registrado | B30: FCC | C30: 59252 | D30: 1 | E30: =IFERROR(VLOOKUP(C30,$U$22:$U$27,1,0),"-") -> - | F30: Imóvel Urbano | G30: Residencial | H30: 2º CRI | I30: Ribeirão Preto/SP | J30: 45219.731 | K30: Nível 2 | L30: =VLOOKUP(C30,[14]Planilha1!M:N,2,0) -> 186500 | M30: 137000 | N30: 1 | O30: =N30*M30 -> 137000 | R30: 78780 | S30: 154000 | W30: #Mat. | X30: VF (R$ )
A31: Registrado | B31: FCC | C31: 59251 | D31: 1 | E31: =IFERROR(VLOOKUP(C31,$U$22:$U$27,1,0),"-") -> - | F31: Imóvel Urbano | G31: Residencial | H31: 2º CRI | I31: Ribeirão Preto/SP | J31: 45219.728 | K31: Nível 2 | L31: =VLOOKUP(C31,[14]Planilha1!M:N,2,0) -> 186500 | M31: 137000 | N31: 1 | O31: =N31*M31 -> 137000 | R31: 78781 | S31: 154000 | V31: Cartas Expedidas | W31: 33 | X31: =W14 -> 12917018 | Y31: =X31/$X$38 -> 0.72276919
A32: Previsão 26/09 | B32: FCC | C32: 102753 | D32: 1 | E32: =IFERROR(VLOOKUP(C32,$U$22:$U$27,1,0),"-") -> - | F32: Imóvel Urbano | G32: Residencial | H32: 1º CRI | I32: Ribeirão Preto/SP | J32: 45117.481 | K32: Nível 2 | L32: =VLOOKUP(C32,[14]Planilha1!M:N,2,0) -> 123500 | M32: 136000 | N32: 1 | O32: =N32*M32 -> 136000 | R32: 78783 | S32: 154000 | V32: Imóvel 96.153 | W32: 1 | X32: 109000 | Y32: =X32/$X$38 -> 0.0060990733
A33: Previsão 26/09 | B33: FCC | C33: 102754 | D33: 1 | E33: =IFERROR(VLOOKUP(C33,$U$22:$U$27,1,0),"-") -> - | F33: Imóvel Urbano | G33: Residencial | H33: 1º CRI | I33: Ribeirão Preto/SP | J33: 45117.485 | K33: Nível 2 | L33: =VLOOKUP(C33,[14]Planilha1!M:N,2,0) -> 123500 | M33: 136000 | N33: 1 | O33: =N33*M33 -> 136000 | R33: 78784 | S33: 154000
A34: Sem Carta | B34: FCC | C34: 36052 | D34: - | E34: Condomínio | F34: Imóvel Urbano | G34: Comercial | H34: 2º CRI | I34: Ribeirão Preto/SP | J34: 45219.701 | K34: Nível 2 | L34: =VLOOKUP(C34,[14]Planilha1!M:N,2,0) -> 132500 | M34: 123000 | N34: 1 | O34: =N34*M34 -> 123000 | R34: 78785 | S34: 154000 | V34: Cartas Pendentes | W34: =SUM(W35:W36) -> 8 | X34: =SUM(X35:X36) -> 4954549 | Y34: =X34/$X$38 -> 0.27723081
A35: Sem Carta | B35: FCC | C35: 36053 | D35: - | E35: Condomínio | F35: Imóvel Urbano | G35: Comercial | H35: 2º CRI | I35: Ribeirão Preto/SP | J35: 45219.713 | K35: Nível 2 | L35: =VLOOKUP(C35,[14]Planilha1!M:N,2,0) -> 132500 | M35: 123000 | N35: 1 | O35: =N35*M35 -> 123000 | R35: 78786 | S35: 154000 | V35: Procuradoria | W35: 6 | X35: =V28 -> 4708549
A36: Previsão 26/09 | B36: Posterior | C36: 6549 | D36: 1 | E36: =IFERROR(VLOOKUP(C36,$U$22:$U$27,1,0),"-") -> - | F36: Imóvel Urbano | G36: Residencial | H36: 1º CRI | I36: Ribeirão Preto/SP | J36: 45117.726 | K36: Nível 2 | L36: n/a | M36: 822000 | N36: 1 | O36: =N36*M36 -> 822000 | R36: 78787 | S36: 154000 | V36: Condomínio | W36: 2 | X36: =X24 -> 246000
A37: Previsão 05/09 | B37: Posterior | C37: 83398 | D37: 1 | E37: =IFERROR(VLOOKUP(C37,$U$22:$U$27,1,0),"-") -> - | F37: Imóvel Urbano | G37: Comercial | H37: 2º CRI | I37: Ribeirão Preto/SP | J37: 45112.497 | K37: Nível 2 | L37: n/a | M37: 710900 | N37: 0.5 | O37: =N37*M37 -> 355450 | R37: 59252 | S37: 137000
A38: Sem Previsão | B38: Posterior | C38: 96153 | D38: 1 | E38: =IFERROR(VLOOKUP(C38,$U$22:$U$27,1,0),"-") -> - | F38: Imóvel Urbano | G38: Residencial | H38: 1º CRI | I38: Ribeirão Preto/SP | J38: 45117.688 | K38: Nível 2 | L38: n/a | M38: 109000 | N38: 1 | O38: =N38*M38 -> 109000 | R38: 59251 | S38: 137000 | V38: Total Imóveis COZAC | W38: =W34+W31 -> 41 | X38: =X34+X31 -> 17871567 | Y38: =X38/$X$38 -> 1
A39: Registrado | B39: Posterior | C39: 96154 | D39: 1 | E39: =IFERROR(VLOOKUP(C39,$U$22:$U$27,1,0),"-") -> - | F39: Imóvel Urbano | G39: Residencial | H39: 1º CRI | I39: Ribeirão Preto/SP | J39: 45117.691 | K39: Nível 2 | L39: n/a | M39: 109000 | N39: 1 | O39: =N39*M39 -> 109000 | R39: 102753 | S39: 136000 | U39: PROCURADORIA
A40: Registrado | B40: Posterior | C40: 96155 | D40: 1 | E40: =IFERROR(VLOOKUP(C40,$U$22:$U$27,1,0),"-") -> - | F40: Imóvel Urbano | G40: Residencial | H40: 1º CRI | I40: Ribeirão Preto/SP | J40: 45117.692 | K40: Nível 2 | L40: n/a | M40: 109000 | N40: 1 | O40: =N40*M40 -> 109000 | R40: 102754 | S40: 136000 | U40: 5104
A41: Registrado | B41: Posterior | C41: 96157 | D41: 1 | E41: =IFERROR(VLOOKUP(C41,$U$22:$U$27,1,0),"-") -> - | F41: Imóvel Urbano | G41: Residencial | H41: 1º CRI | I41: Ribeirão Preto/SP | J41: 45117.713 | K41: Nível 2 | L41: n/a | M41: 62000 | N41: 1 | O41: =N41*M41 -> 62000 | R41: 96153 | S41: 109000 | U41: 5103
...

Sheet Listagem Imobiliária-23-01-26
A1: Mensagens | B1: ID Caso | C1: Nome do Caso | D1: Matrícula(s) | E1: Valor Avaliação | F1: Valor Venda Forçada | G1: Valor Venda Forçada VP | H1: Classe Imóvel | I1: Tipo do Imóvel | J1: Cidade | K1: UF | L1: Resultado de localização | M1: Nível | N1: Tarefa Atual | O1: Solicitante | P1: Área Demandante | Q1: Responsável (Tarefa Atual) | R1: Status (Tarefa Atual) | S1: Prazo - Tarefa atual | T1: Data/Hora de Criação (Solicitação) | U1: Data/Hora de Criação (Tarefa atual) | V1: Data/Hora de Atribuição (Tarefa atual) | W1: Data/Hora de Conclusão (Tarefa atual) | X1: Data/Hora de Conclusão (Tarefa atual) | Y1: Tags | Z1: Finalidade da tarefa | AA1: Nome da Carteira | AB1: Logradouro | AC1: Bairro | AD1: Área Construída (m²) | AE1: Área Privativa (m²) | AF1: Área Terreno | AG1: Unid. Área Terreno | AH1: Tentativa de localização | AI1: Tipo de localização | AJ1: Resultado da Tarefa de localização | AK1: Complexidade da localização | AL1: Prazo entrega - Localização | AM1: Data/Hora de Criação de localização | AN1: Data/Hora de atribuição - Localização | AO1: Data/Hora de conclusão - Localização | AP1: Responsável localização | AQ1: Resultado da avaliação | AR1: Resultado da Tarefa de avaliação | AS1: Complexidade da avaliação | AT1: Prazo entrega - Avaliação | AU1: Data/Hora de Criação de avaliação | AV1: Data/Hora de atribuição - Avaliação | AW1: Data/Hora de conclusão - Avaliação | AX1: Responsável avaliação | AY1: Resultado da validação | AZ1: Resultado da Tarefa de validação | BA1: Complexidade da validação | BB1: Prazo entrega - Validação | BC1: Data/Hora de Criação de validação | BD1: Data/Hora de atribuição - Validação | BE1: Data/Hora de conclusão - Validação | BF1: Responsável validação | BG1: Correção diligente? | BH1: Revalidação? | BI1: Cancelado por: | BJ1: Justificativa do cancelamento: | BK1: Somente localização? | BL1: Comentário:
B2: 15292 | C2: COZAC | D2: 149 | E2: 297000 | F2: 228000 | H2: Imóvel Urbano | I2: Loja de rua | J2: Ribeirão Preto | K2: SP | L2: Localizado | M2: Nível 2 | N2: Validação Avaliação Urbano | O2: ANA CLARA | P2: Gestão BNDU | Q2: ANDERSON SCARPINO | R2: Concluída | S2: 18/07/2025 | T2: 05/06/2025 17:20 | U2: 18/07/2025 09:16 | V2: 18/07/2025 09:25 | W2: 18/07/2025 09:51 | X2: =W2*1 -> 45856.41 | Z2: Pesquisa de Bens | AA2: BANCO DO BRASIL (SGL_NAME) | AB2: Rua Comandante Marcondes Salgado | AC2: Centro | AD2: 99.27 | AF2: 130 | AG2: m2 | AH2: T1 | AI2: Remota | AJ2: Concluido | AK2: Normal | AL2: 04/04/2025 | AM2: 02/04/2025 16:10 | AN2: 02/04/2025 16:11 | AO2: 02/04/2025 19:11 | AP2: RAMON GOMES | AT2: 31/07/2025 | AU2: 18/07/2025 09:16 | AV2: 01/07/2025 11:55 | AW2: 18/07/2025 09:16 | AX2: Victor Libarino | BB2: 18/07/2025 | BC2: 18/07/2025 09:16 | BD2: 18/07/2025 09:25 | BE2: 18/07/2025 09:51 | BF2: ANDERSON SCARPINO | BH2: FALSE | BK2: FALSE
B3: 15292 | C3: COZAC | D3: 149 | E3: 405000 | F3: 311000 | H3: Imóvel Urbano | I3: Casa Residencial | J3: Ribeirão Preto | K3: SP | L3: Localizado | M3: Nível 2 | N3: Validação Avaliação Urbano | O3: LUCAS ORTEGA | Q3: ANDERSON SCARPINO | R3: Concluída | S3: 20/10/2023 | T3: 13/06/2023 15:01 | U3: 20/10/2023 16:12 | V3: 20/10/2023 16:12 | W3: 20/10/2023 16:39 | X3: =W3*1 -> 45219.694 | Z3: Acordo | AA3: BANCO DO BRASIL (SGL_NAME) | AB3: Rua Acre | AC3: Ipiranga | AD3: 200 | AF3: 480 | AG3: m2 | AH3: T1 | AI3: Remota | AJ3: Concluido | AL3: 05/04/2023 | AM3: 29/03/2023 17:40 | AN3: 29/03/2023 17:42 | AO3: 31/03/2023 09:55 | AP3: AGROFFICIO ATENDIMENTO | AT3: 10/07/2023 | AU3: 20/10/2023 16:12 | AV3: 10/07/2023 11:50 | AW3: 10/07/2023 12:16 | AX3: RAPHAEL PARENTE | BB3: 20/10/2023 | BC3: 20/10/2023 16:12 | BD3: 20/10/2023 16:12 | BE3: 20/10/2023 16:39 | BF3: ANDERSON SCARPINO | BG3: TRUE | BH3: TRUE | BK3: FALSE
B4: 15292 | C4: COZAC | D4: 149 | E4: 307028.72 | F4: 221060.68 | H4: Imóvel Urbano | I4: Casa Residencial | J4: Ribeirão Preto | K4: SP | L4: Localizado | M4: Nível 1 | N4: Validação Avaliação Urbano | O4: LUCAS ORTEGA | Q4: MATHEUS NAVARRO | R4: Concluída | S4: 20/04/2023 | T4: 29/03/2023 17:40 | U4: 10/04/2023 12:01 | V4: 14/04/2023 10:35 | W4: 19/04/2023 18:28 | X4: =W4*1 -> 45035.769 | Z4: Pesquisa de Bens | AA4: BANCO DO BRASIL (SGL_NAME) | AB4: Rua Acre | AC4: Ipiranga | AD4: 196.13 | AF4: 480 | AG4: m2 | AH4: T1 | AI4: Remota | AJ4: Concluido | AL4: 05/04/2023 | AM4: 29/03/2023 17:40 | AN4: 29/03/2023 17:42 | AO4: 31/03/2023 09:55 | AP4: AGROFFICIO ATENDIMENTO | AQ4: Avaliado | AR4: Concluido | AS4: Normal | AT4: 10/04/2023 | AU4: 10/04/2023 12:01 | AV4: 03/04/2023 09:08 | AW4: 10/04/2023 12:01 | AX4: RAIZA GONÇALVES | AY4: Avaliado | AZ4: Concluido | BA4: Normal | BB4: 20/04/2023 | BC4: 10/04/2023 12:01 | BD4: 14/04/2023 10:35 | BE4: 19/04/2023 18:28 | BF4: MATHEUS NAVARRO | BH4: FALSE | BK4: FALSE
B5: 15292 | C5: COZAC | D5: 149 | E5: 238460 | F5: 164537 | H5: Imóvel Urbano | I5: Casa Residencial | J5: Ribeirão Preto | K5: SP | L5: Localizado | M5: Nível 1 | N5: Validação Avaliação Urbano | O5: rd.avaliacao@enforcegroup.com.br | Q5: BRUNO ICARO | R5: Concluída | S5: 27/06/2022 | T5: 27/05/2022 08:40 | U5: 26/05/2022 21:00 | V5: 12/06/2022 21:00 | W5: 14/06/2022 21:00 | X5: =W5*1 -> 44726.875 | Y5: MIGRADO_ZOHO | Z5: Pesquisa de Bens | AA5: BANCO DO BRASIL (SGL_NAME) | AB5: Rua Acre, 1839 | AC5: Ipiranga | AD5: 330 | AE5: 0 | AF5: 480 | AG5: m2 | AH5: T1 | AI5: Remota | AJ5: Concluido | AL5: 02/06/2022 | AM5: 26/05/2022 21:00 | AN5: 26/05/2022 21:00 | AO5: 01/06/2022 21:00 | AP5: HERGOM | AQ5: Avaliado | AS5: Normal | AT5: 27/06/2022 | AU5: 26/05/2022 21:00 | AV5: 12/06/2022 21:00 | AW5: 14/06/2022 21:00 | AX5: BRUNO ICARO | AY5: Avaliado | BB5: 27/06/2022 | BC5: 14/06/2022 21:00 | BD5: 12/06/2022 21:00 | BE5: 29/06/2022 21:00 | BF5: MARINA FAHL | BH5: FALSE | BK5: FALSE
B6: 15292 | C6: COZAC | D6: 3417 | E6: 579000 | F6: 446000 | H6: Imóvel Urbano | I6: Casa Residencial | J6: Ribeirão Preto | K6: SP | L6: Localizado | M6: Nível 2 | N6: Validação Avaliação Urbano | O6: ANA CLARA | P6: Gestão BNDU | Q6: ANDERSON SCARPINO | R6: Concluída | S6: 10/07/2025 | T6: 05/06/2025 17:16 | U6: 10/07/2025 02:21 | V6: 10/07/2025 09:33 | W6: 10/07/2025 11:07 | X6: =W6*1 -> 45848.463 | Z6: Pesquisa de Bens | AA6: BANCO DO BRASIL (SGL_NAME) | AB6: Rua Conde Afonso Celso | AC6: Jardim Sumaré | AD6: 217.23 | AF6: 352 | AG6: m2 | AH6: T1 | AI6: Remota | AJ6: Concluido | AL6: 05/04/2023 | AM6: 28/03/2023 17:58 | AN6: 29/03/2023 09:03 | AO6: 31/03/2023 10:14 | AP6: AGROFFICIO ATENDIMENTO | AT6: 31/07/2025 | AU6: 10/07/2025 02:21 | AV6: 01/07/2025 11:55 | AW6: 10/07/2025 02:21 | AX6: Victor Libarino | BB6: 10/07/2025 | BC6: 10/07/2025 02:21 | BD6: 10/07/2025 09:33 | BE6: 10/07/2025 11:07 | BF6: ANDERSON SCARPINO | BH6: FALSE | BK6: FALSE
B7: 15292 | C7: COZAC | D7: 3417 | E7: 600000 | F7: 462000 | H7: Imóvel Urbano | I7: Casa Residencial | J7: Ribeirão Preto | K7: SP | L7: Localizado | M7: Nível 2 | N7: Validação Avaliação Urbano | O7: LUCAS ORTEGA | Q7: ANDERSON SCARPINO | R7: Concluída | S7: 20/10/2023 | T7: 13/06/2023 15:02 | U7: 20/10/2023 16:20 | V7: 20/10/2023 16:21 | W7: 20/10/2023 16:24 | X7: =W7*1 -> 45219.683 | Z7: Acordo | AA7: BANCO DO BRASIL (SGL_NAME) | AB7: Rua Conde Afonso Celso | AC7: Jardim Sumaré | AD7: 190 | AF7: 352 | AG7: m2 | AH7: T1 | AI7: Remota | AJ7: Concluido | AL7: 05/04/2023 | AM7: 28/03/2023 17:58 | AN7: 29/03/2023 09:03 | AO7: 31/03/2023 10:14 | AP7: AGROFFICIO ATENDIMENTO | AT7: 29/06/2023 | AU7: 20/10/2023 16:20 | AV7: 13/06/2023 15:22 | AW7: 03/07/2023 13:53 | AX7: RAPHAEL PARENTE | BB7: 20/10/2023 | BC7: 20/10/2023 16:20 | BD7: 20/10/2023 16:21 | BE7: 20/10/2023 16:24 | BF7: ANDERSON SCARPINO | BH7: TRUE | BK7: FALSE
B8: 15292 | C8: COZAC | D8: 3417 | E8: 573295.03 | F8: 412772.42 | H8: Imóvel Urbano | I8: Casa Residencial | J8: Ribeirão Preto | K8: SP | L8: Localizado | M8: Nível 1 | N8: Validação Avaliação Urbano | O8: NATHALIA DIAS | P8: Investigação | Q8: MATHEUS NAVARRO | R8: Concluída | S8: 20/04/2023 | T8: 28/03/2023 17:58 | U8: 06/04/2023 09:33 | V8: 14/04/2023 10:35 | W8: 19/04/2023 18:23 | X8: =W8*1 -> 45035.766 | Z8: Pesquisa de Bens | AA8: BANCO DO BRASIL (SGL_NAME) | AB8: Rua Conde Afonso Celso | AC8: Jardim Sumaré | AD8: 160 | AF8: 352 | AG8: m2 | AH8: T1 | AI8: Remota | AJ8: Concluido | AL8: 05/04/2023 | AM8: 28/03/2023 17:58 | AN8: 29/03/2023 09:03 | AO8: 31/03/2023 10:14 | AP8: AGROFFICIO ATENDIMENTO | AQ8: Avaliado | AR8: Concluido | AS8: Normal | AT8: 06/04/2023 | AU8: 06/04/2023 09:33 | AV8: 06/04/2023 09:22 | AW8: 06/04/2023 09:33 | AX8: RAIZA GONÇALVES | AY8: Avaliado | AZ8: Concluido | BA8: Réplica | BB8: 20/04/2023 | BC8: 06/04/2023 09:33 | BD8: 14/04/2023 10:35 | BE8: 19/04/2023 18:23 | BF8: MATHEUS NAVARRO | BG8: TRUE | BH8: FALSE | BK8: FALSE
B9: 15292 | C9: COZAC | D9: 3417 | E9: 850560 | F9: 637920 | H9: Imóvel Urbano | I9: Casa Residencial | J9: Ribeirão Preto | K9: SP | L9: Localizado | M9: Nível 0 | N9: Validação Avaliação Urbano | O9: rd.avaliacao@enforcegroup.com.br | Q9: MATHEUS NAVARRO | R9: Concluída | S9: 28/08/2022 | T9: 28/07/2022 14:45 | U9: 27/07/2022 21:00 | V9: 28/07/2022 21:00 | W9: 28/07/2022 21:00 | X9: =W9*1 -> 44770.875 | Y9: MIGRADO_ZOHO | Z9: Pesquisa de Bens | AA9: BANCO DO BRASIL (SGL_NAME) | AB9: Rua Conde Afonso Celso, 1453 | AC9: Jardim Sumaré | AD9: 350 | AE9: 0 | AF9: 1109 | AG9: m2 | AH9: T1 | AI9: Remota | AJ9: Concluido | AL9: 28/07/2022 | AM9: 27/07/2022 21:00 | AN9: 27/07/2022 21:00 | AO9: 27/07/2022 21:00 | AP9: SIGLOCAL | AQ9: Avaliado | AT9: 28/08/2022 | AU9: 27/07/2022 21:00 | AV9: 28/07/2022 21:00 | AW9: 28/07/2022 21:00 | AX9: MATHEUS NAVARRO | AY9: Avaliado | BB9: 28/08/2022 | BC9: 28/07/2022 21:00 | BD9: 28/07/2022 21:00 | BE9: 28/07/2022 21:00 | BF9: MATHEUS NAVARRO | BH9: FALSE | BK9: FALSE
B10: 15292 | C10: COZAC | D10: 3417 | E10: 528068 | F10: 380209 | H10: Imóvel Urbano | I10: Casa Residencial | J10: Ribeirão Preto | K10: SP | L10: Localizado | M10: Nível 1 | N10: Validação Avaliação Urbano | O10: rd.avaliacao@enforcegroup.com.br | Q10: JULIA JORGE | R10: Concluída | S10: 27/06/2022 | T10: 27/05/2022 08:48 | U10: 26/05/2022 21:00 | V10: 12/06/2022 21:00 | W10: 15/06/2022 21:00 | X10: =W10*1 -> 44727.875 | Y10: MIGRADO_ZOHO | Z10: Pesquisa de Bens | AA10: BANCO DO BRASIL (SGL_NAME) | AB10: Rua Conde Afonso Celso, 1453 | AC10: Jardim Sumaré | AD10: 190 | AE10: 0 | AF10: 352 | AG10: m2 | AH10: T1 | AI10: Remota | AJ10: Concluido | AL10: 02/06/2022 | AM10: 26/05/2022 21:00 | AN10: 26/05/2022 21:00 | AO10: 01/06/2022 21:00 | AP10: HERGOM | AQ10: Avaliado | AS10: Normal | AT10: 27/06/2022 | AU10: 26/05/2022 21:00 | AV10: 12/06/2022 21:00 | AW10: 15/06/2022 21:00 | AX10: JULIA JORGE | AY10: Avaliado | BB10: 27/06/2022 | BC10: 15/06/2022 21:00 | BD10: 12/06/2022 21:00 | BE10: 29/06/2022 21:00 | BF10: MARINA FAHL | BH10: FALSE | BK10: FALSE
B11: 15292 | C11: COZAC | D11: 5103 | E11: 536000 | F11: 391000 | H11: Imóvel Urbano | I11: Casa Residencial | J11: Ribeirão Preto | K11: SP | L11: Localizado | M11: Nível 2 | N11: Validação Avaliação Urbano | O11: FERNANDA GOMES | P11: Gestão BNDU | Q11: ANDERSON SCARPINO | R11: Concluída | S11: 13/01/2026 | T11: 19/12/2025 16:50 | U11: 11/01/2026 15:36 | V11: 13/01/2026 11:03 | W11: 13/01/2026 12:45 | X11: =W11*1 -> 46035.531 | Z11: Pesquisa de Bens | AA11: BANCO DO BRASIL (SGL_NAME) | AB11: Rua João Penteado | AC11: Jardim Sumaré | AD11: 336.6 | AF11: 312.5 | AG11: m2 | AH11: T1 | AI11: Remota | AJ11: Concluido | AL11: 05/04/2023 | AM11: 28/03/2023 17:56 | AN11: 29/03/2023 09:02 | AO11: 31/03/2023 10:48 | AP11: AGROFFICIO ATENDIMENTO | AT11: 16/01/2026 | AU11: 11/01/2026 15:36 | AV11: 19/12/2025 17:33 | AW11: 11/01/2026 15:36 | AX11: Victor Libarino - Financeiro (N2/N3) | BB11: 13/01/2026 | BC11: 11/01/2026 15:36 | BD11: 13/01/2026 11:03 | BE11: 13/01/2026 12:45 | BF11: ANDERSON SCARPINO | BH11: FALSE | BK11: FALSE
B12: 15292 | C12: COZAC | D12: 5103 | E12: 571000 | F12: 439000 | H12: Imóvel Urbano | I12: Casa Comercial | J12: Ribeirão Preto | K12: SP | L12: Localizado | M12: Nível 2 | N12: Validação Avaliação Urbano | O12: LUCAS ORTEGA | Q12: ANDERSON SCARPINO | R12: Concluída | S12: 20/10/2023 | T12: 13/06/2023 15:00 | U12: 20/10/2023 16:29 | V12: 20/10/2023 16:30 | W12: 20/10/2023 16:36 | X12: =W12*1 -> 45219.692 | Z12: Acordo | AA12: BANCO DO BRASIL (SGL_NAME) | AB12: Rua João Penteado | AC12: Jardim Sumaré | AD12: 324.6 | AF12: 312.5 | AG12: m2 | AH12: T1 | AI12: Remota | AJ12: Concluido | AL12: 05/04/2023 | AM12: 28/03/2023 17:56 | AN12: 29/03/2023 09:02 | AO12: 31/03/2023 10:48 | AP12: AGROFFICIO ATENDIMENTO | AT12: 06/07/2023 | AU12: 20/10/2023 16:29 | AV12: 13/06/2023 15:29 | AW12: 03/07/2023 10:48 | AX12: RAPHAEL PARENTE | BB12: 20/10/2023 | BC12: 20/10/2023 16:29 | BD12: 20/10/2023 16:30 | BE12: 20/10/2023 16:36 | BF12: ANDERSON SCARPINO | BH12: TRUE | BK12: FALSE
B13: 15292 | C13: COZAC | D13: 5103 | E13: 701861.9 | F13: 512359.18 | H13: Imóvel Urbano | I13: Casa Residencial | J13: Ribeirão Preto | K13: SP | L13: Localizado | M13: Nível 1 | N13: Validação Avaliação Urbano | O13: NATHALIA DIAS | P13: Investigação | Q13: MATHEUS NAVARRO | R13: Concluída | S13: 20/04/2023 | T13: 28/03/2023 17:56 | U13: 06/04/2023 11:17 | V13: 14/04/2023 10:35 | W13: 19/04/2023 18:13 | X13: =W13*1 -> 45035.759 | Z13: Pesquisa de Bens | AA13: BANCO DO BRASIL (SGL_NAME) | AB13: Rua João Penteado | AC13: Jardim Sumaré | AD13: 324.6 | AF13: 312.5 | AG13: m2 | AH13: T1 | AI13: Remota | AJ13: Concluido | AL13: 05/04/2023 | AM13: 28/03/2023 17:56 | AN13: 29/03/2023 09:02 | AO13: 31/03/2023 10:48 | AP13: AGROFFICIO ATENDIMENTO | AQ13: Avaliado | AR13: Concluido | AS13: Normal | AT13: 10/04/2023 | AU13: 06/04/2023 11:17 | AV13: 03/04/2023 09:08 | AW13: 06/04/2023 11:17 | AX13: RAIZA GONÇALVES | AY13: Avaliado | AZ13: Concluido | BA13: Normal | BB13: 20/04/2023 | BC13: 06/04/2023 11:17 | BD13: 14/04/2023 10:35 | BE13: 19/04/2023 18:13 | BF13: MATHEUS NAVARRO | BH13: FALSE | BK13: FALSE
B14: 15292 | C14: COZAC | D14: 5103 | E14: 524177 | F14: 382650 | H14: Imóvel Urbano | I14: Prédio Comercial | J14: Ribeirão Preto | K14: SP | L14: Localizado | M14: Nível 1 | N14: Validação Avaliação Urbano | O14: rd.avaliacao@enforcegroup.com.br | Q14: BRUNO ICARO | R14: Concluída | S14: 28/08/2022 | T14: 28/07/2022 14:42 | U14: 27/07/2022 21:00 | V14: 28/07/2022 21:00 | W14: 28/07/2022 21:00 | X14: =W14*1 -> 44770.875 | Y14: MIGRADO_ZOHO | Z14: Pesquisa de Bens | AA14: BANCO DO BRASIL (SGL_NAME) | AB14: Rua João Penteado, 90 | AC14: Jardim America | AD14: 250 | AE14: 0 | AF14: 312.5 | AG14: m2 | AH14: T1 | AI14: Remota | AJ14: Concluido | AL14: 28/07/2022 | AM14: 27/07/2022 21:00 | AN14: 27/07/2022 21:00 | AO14: 27/07/2022 21:00 | AP14: SIGLOCAL | AQ14: Avaliado | AS14: Normal | AT14: 28/08/2022 | AU14: 27/07/2022 21:00 | AV14: 28/07/2022 21:00 | AW14: 28/07/2022 21:00 | AX14: BRUNO ICARO | AY14: Avaliado | BB14: 28/08/2022 | BC14: 28/07/2022 21:00 | BD14: 28/07/2022 21:00 | BE14: 28/07/2022 21:00 | BF14: MATHEUS NAVARRO | BH14: FALSE | BK14: FALSE
B15: 15292 | C15: COZAC | D15: 5103 | E15: 596457 | F15: 417520 | H15: Imóvel Urbano | I15: Casa Residencial | J15: Ribeirão Preto | K15: SP | L15: Localizado | M15: Nível 1 | N15: Validação Avaliação Urbano | O15: rd.avaliacao@enforcegroup.com.br | Q15: JULIA JORGE | R15: Concluída | S15: 27/06/2022 | T15: 27/05/2022 08:48 | U15: 26/05/2022 21:00 | V15: 12/06/2022 21:00 | W15: 15/06/2022 21:00 | X15: =W15*1 -> 44727.875 | Y15: MIGRADO_ZOHO | Z15: Pesquisa de Bens | AA15: BANCO DO BRASIL (SGL_NAME) | AB15: Rua João Penteado, 90 | AC15: Jardim Sumaré | AD15: 230 | AE15: 0 | AF15: 312.5 | AG15: m2 | AH15: T1 | AI15: Remota | AJ15: Concluido | AL15: 02/06/2022 | AM15: 26/05/2022 21:00 | AN15: 26/05/2022 21:00 | AO15: 01/06/2022 21:00 | AP15: HERGOM | AQ15: Avaliado | AS15: Normal | AT15: 27/06/2022 | AU15: 26/05/2022 21:00 | AV15: 12/06/2022 21:00 | AW15: 15/06/2022 21:00 | AX15: JULIA JORGE | AY15: Avaliado | BB15: 27/06/2022 | BC15: 15/06/2022 21:00 | BD15: 12/06/2022 21:00 | BE15: 29/06/2022 21:00 | BF15: MARINA FAHL | BH15: FALSE | BK15: FALSE
B16: 15292 | C16: COZAC | D16: 5104 | E16: 1003000 | F16: 732000 | H16: Imóvel Urbano | I16: Prédio residencial | J16: Ribeirão Preto | K16: SP | L16: Localizado | M16: Nível 2 | N16: Validação Avaliação Urbano | O16: MATHEUS TORRES | P16: Gestão BNDU | Q16: ANDERSON SCARPINO | R16: Concluída | S16: 19/12/2025 | T16: 25/11/2025 16:09 | U16: 15/12/2025 11:07 | V16: 19/12/2025 08:49 | W16: 19/12/2025 09:30 | X16: =W16*1 -> 46010.396 | Z16: Pesquisa de Bens | AA16: BANCO DO BRASIL (SGL_NAME) | AB16: Avenida Santa Luzia | AC16: Jardim Sumaré | AD16: 669.16 | AF16: 433.01 | AG16: m2 | AH16: T1 | AI16: Remota | AJ16: Concluido | AL16: 05/04/2023 | AM16: 29/03/2023 17:31 | AN16: 29/03/2023 17:36 | AO16: 05/04/2023 15:17 | AP16: AGROFFICIO ATENDIMENTO | AT16: 22/12/2025 | AU16: 15/12/2025 11:07 | AV16: 01/12/2025 14:30 | AW16: 15/12/2025 11:07 | AX16: Victor Libarino (N2/N3) | BB16: 19/12/2025 | BC16: 15/12/2025 11:07 | BD16: 19/12/2025 08:49 | BE16: 19/12/2025 09:30 | BF16: ANDERSON SCARPINO | BH16: FALSE | BK16: FALSE
B17: 15292 | C17: COZAC | D17: 5104 | E17: 1024000 | F17: 727000 | H17: Imóvel Urbano | I17: Casa Comercial | J17: Ribeirão Preto | K17: SP | L17: Localizado | M17: Nível 2 | N17: Validação Avaliação Urbano | O17: LUCAS ORTEGA | Q17: ANDERSON SCARPINO | R17: Concluída | S17: 10/07/2023 | T17: 13/06/2023 15:02 | U17: 10/07/2023 14:57 | V17: 10/07/2023 15:05 | W17: 10/07/2023 15:05 | X17: =W17*1 -> 45117.628 | Z17: Prospecção | AA17: BANCO DO BRASIL (SGL_NAME) | AB17: Avenida Santa Luzia | AC17: Jardim Sumaré | AD17: 669.16 | AF17: 433.01 | AG17: m2 | AH17: T1 | AI17: Remota | AJ17: Concluido | AL17: 05/04/2023 | AM17: 29/03/2023 17:31 | AN17: 29/03/2023 17:36 | AO17: 05/04/2023 15:17 | AP17: AGROFFICIO ATENDIMENTO | AT17: 10/07/2023 | AU17: 10/07/2023 14:57 | AV17: 10/07/2023 14:33 | AW17: 10/07/2023 14:57 | AX17: RAPHAEL PARENTE | BB17: 10/07/2023 | BC17: 10/07/2023 14:57 | BD17: 10/07/2023 15:05 | BE17: 10/07/2023 15:05 | BF17: ANDERSON SCARPINO | BG17: TRUE | BH17: FALSE | BK17: FALSE
B18: 15292 | C18: COZAC | D18: 5104 | E18: 1322517.2 | F18: 965437.56 | H18: Imóvel Urbano | I18: Casa Residencial | J18: Ribeirão Preto | K18: SP | L18: Localizado | M18: Nível 1 | N18: Validação Avaliação Urbano | O18: NATHALIA DIAS | P18: Investigação | Q18: MATHEUS NAVARRO | R18: Concluída | S18: 20/04/2023 | T18: 29/03/2023 17:31 | U18: 18/04/2023 12:41 | V18: 18/04/2023 16:38 | W18: 19/04/2023 18:16 | X18: =W18*1 -> 45035.761 | Z18: Pesquisa de Bens | AA18: BANCO DO BRASIL (SGL_NAME) | AB18: Avenida Santa Luzia | AC18: Jardim Sumaré | AD18: 669.16 | AF18: 433.01 | AG18: m2 | AH18: T1 | AI18: Remota | AJ18: Concluido | AL18: 05/04/2023 | AM18: 29/03/2023 17:31 | AN18: 29/03/2023 17:36 | AO18: 05/04/2023 15:17 | AP18: AGROFFICIO ATENDIMENTO | AQ18: Avaliado | AR18: Concluido | AS18: Normal | AT18: 18/04/2023 | AU18: 18/04/2023 12:41 | AV18: 06/04/2023 08:21 | AW18: 18/04/2023 12:41 | AX18: RAIZA GONÇALVES | AY18: Avaliado | AZ18: Concluido | BA18: Réplica | BB18: 20/04/2023 | BC18: 18/04/2023 12:41 | BD18: 18/04/2023 16:38 | BE18: 19/04/2023 18:16 | BF18: MATHEUS NAVARRO | BH18: FALSE | BK18: FALSE
B19: 15292 | C19: COZAC | D19: 5104 | E19: 892466 | F19: 687199 | H19: Imóvel Urbano | I19: Prédio Comercial | J19: Ribeirão Preto | K19: SP | L19: Localizado | M19: Nível 1 | N19: Validação Avaliação Urbano | O19: rd.avaliacao@enforcegroup.com.br | Q19: BRUNO ICARO | R19: Concluída | S19: 28/08/2022 | T19: 28/07/2022 14:41 | U19: 27/07/2022 21:00 | V19: 28/07/2022 21:00 | W19: 28/07/2022 21:00 | X19: =W19*1 -> 44770.875 | Y19: MIGRADO_ZOHO | Z19: Pesquisa de Bens | AA19: BANCO DO BRASIL (SGL_NAME) | AB19: Avenida Santa Luzia, 111 | AC19: Jardim Sumare | AD19: 350 | AE19: 0 | AF19: 430 | AG19: m2 | AH19: T1 | AI19: Remota | AJ19: Concluido | AL19: 28/07/2022 | AM19: 27/07/2022 21:00 | AN19: 27/07/2022 21:00 | AO19: 27/07/2022 21:00 | AP19: SIGLOCAL | AQ19: Avaliado | AS19: Normal | AT19: 28/08/2022 | AU19: 27/07/2022 21:00 | AV19: 28/07/2022 21:00 | AW19: 28/07/2022 21:00 | AX19: BRUNO ICARO | AY19: Avaliado | BB19: 28/08/2022 | BC19: 28/07/2022 21:00 | BD19: 28/07/2022 21:00 | BE19: 28/07/2022 21:00 | BF19: MATHEUS NAVARRO | BH19: FALSE | BK19: FALSE
B20: 15292 | C20: COZAC | D20: 5104 | E20: 987573 | F20: 760431 | H20: Imóvel Urbano | I20: Prédio Comercial | J20: Ribeirão Preto | K20: SP | L20: Localizado | M20: Nível 1 | N20: Validação Avaliação Urbano | O20: rd.avaliacao@enforcegroup.com.br | Q20: BRUNO ICARO | R20: Concluída | S20: 27/06/2022 | T20: 27/05/2022 08:44 | U20: 26/05/2022 21:00 | V20: 12/06/2022 21:00 | W20: 14/06/2022 21:00 | X20: =W20*1 -> 44726.875 | Y20: MIGRADO_ZOHO | Z20: Pesquisa de Bens | AA20: BANCO DO BRASIL (SGL_NAME) | AB20: Avenida Santa Luzia, 111 | AC20: Jardim Sumaré | AD20: 699.16 | AE20: 0 | AF20: 433.01 | AG20: m2 | AH20: T1 | AI20: Remota | AJ20: Concluido | AL20: 02/06/2022 | AM20: 26/05/2022 21:00 | AN20: 26/05/2022 21:00 | AO20: 01/06/2022 21:00 | AP20: HERGOM | AQ20: Avaliado | AS20: Normal | AT20: 27/06/2022 | AU20: 26/05/2022 21:00 | AV20: 12/06/2022 21:00 | AW20: 14/06/2022 21:00 | AX20: BRUNO ICARO | AY20: Avaliado | BB20: 27/06/2022 | BC20: 14/06/2022 21:00 | BD20: 12/06/2022 21:00 | BE20: 29/06/2022 21:00 | BF20: MARINA FAHL | BH20: FALSE | BK20: FALSE
B21: 15292 | C21: COZAC | D21: 6529 | E21: 418000 | F21: 293000 | H21: Imóvel Urbano | I21: Terreno urbano | J21: Ribeirão Preto | K21: SP | L21: Localizado | M21: Nível 2 | N21: Validação Avaliação Urbano | O21: FERNANDA GOMES | P21: Gestão BNDU | Q21: ANDERSON SCARPINO | R21: Concluída | S21: 07/10/2025 | T21: 19/09/2025 10:11 | U21: 06/10/2025 17:49 | V21: 07/10/2025 09:12 | W21: 07/10/2025 10:19 | X21: =W21*1 -> 45937.43 | Z21: Pesquisa de Bens | AA21: BANCO DO BRASIL (SGL_NAME) | AB21: Rua Marino Paterlini | AC21: Presidente Médici | AF21: 395 | AG21: m2 | AH21: T1 | AI21: Remota | AJ21: Concluido | AL21: 04/04/2023 | AM21: 28/03/2023 17:10 | AN21: 29/03/2023 09:08 | AO21: 04/04/2023 11:27 | AP21: SIGLOCAL ACESSO | AT21: 08/10/2025 | AU21: 06/10/2025 17:49 | AV21: 24/09/2025 11:30 | AW21: 06/10/2025 17:49 | AX21: Victor Libarino | BB21: 07/10/2025 | BC21: 06/10/2025 17:49 | BD21: 07/10/2025 09:12 | BE21: 07/10/2025 10:19 | BF21: ANDERSON SCARPINO | BH21: FALSE | BK21: FALSE
B22: 15292 | C22: COZAC | D22: 6529 | E22: 284000 | F22: 230000 | H22: Imóvel Urbano | I22: Terreno urbano | J22: Ribeirão Preto | K22: SP | L22: Localizado | M22: Nível 2 | N22: Validação Avaliação Urbano | O22: THIAGO MACHADO | P22: GESTÃO PORTFÓLIO | Q22: ANDERSON SCARPINO | R22: Concluída | S22: 20/10/2023 | T22: 06/06/2023 16:39 | U22: 20/10/2023 16:40 | V22: 20/10/2023 16:40 | W22: 20/10/2023 16:43 | X22: =W22*1 -> 45219.697 | Z22: Acordo | AA22: BANCO DO BRASIL (SGL_NAME) | AB22: Rua Marino Paterlini | AC22: Presidente Médici | AF22: 395 | AG22: m2 | AH22: T1 | AI22: Remota | AJ22: Concluido | AL22: 04/04/2023 | AM22: 28/03/2023 17:10 | AN22: 29/03/2023 09:08 | AO22: 04/04/2023 11:27 | AP22: SIGLOCAL ACESSO | AT22: 10/07/2023 | AU22: 20/10/2023 16:40 | AV22: 10/07/2023 15:25 | AW22: 10/07/2023 15:32 | AX22: RAPHAEL PARENTE | BB22: 20/10/2023 | BC22: 20/10/2023 16:40 | BD22: 20/10/2023 16:40 | BE22: 20/10/2023 16:43 | BF22: ANDERSON SCARPINO | BG22: TRUE | BH22: TRUE | BK22: FALSE
B23: 15292 | C23: COZAC | D23: 6529 | E23: 219785.99 | F23: 178026.65 | H23: Imóvel Urbano | I23: Terreno urbano | J23: Ribeirão Preto | K23: SP | L23: Localizado | M23: Nível 1 | N23: Validação Avaliação Urbano | O23: NATHALIA DIAS | P23: Investigação | Q23: MATHEUS NAVARRO | R23: Concluída | S23: 20/04/2023 | T23: 28/03/2023 17:10 | U23: 17/04/2023 14:54 | V23: 17/04/2023 16:04 | W23: 20/04/2023 11:24 | X23: =W23*1 -> 45036.475 | Z23: Pesquisa de Bens | AA23: BANCO DO BRASIL (SGL_NAME) | AB23: Rua Marino Paterlini | AC23: Presidente Médici | AF23: 395 | AG23: m2 | AH23: T1 | AI23: Remota | AJ23: Concluido | AL23: 04/04/2023 | AM23: 28/03/2023 17:10 | AN23: 29/03/2023 09:08 | AO23: 04/04/2023 11:27 | AP23: SIGLOCAL ACESSO | AQ23: Avaliado | AR23: Concluido | AS23: Réplica | AT23: 18/04/2023 | AU23: 17/04/2023 14:54 | AV23: 06/04/2023 08:20 | AW23: 17/04/2023 14:54 | AX23: RAIZA GONÇALVES | AY23: Avaliado | AZ23: Concluido | BA23: Réplica | BB23: 20/04/2023 | BC23: 17/04/2023 14:54 | BD23: 17/04/2023 16:04 | BE23: 20/04/2023 11:24 | BF23: MATHEUS NAVARRO | BH23: FALSE | BK23: FALSE
B24: 15292 | C24: COZAC | D24: 6529 | E24: 222768 | F24: 178214 | H24: Imóvel Urbano | I24: Terreno urbano | J24: Ribeirão Preto | K24: SP | L24: Localizado | M24: Nível 0 | N24: Validação Avaliação Urbano | O24: rd.avaliacao@enforcegroup.com.br | Q24: ANDRE MAGIORE | R24: Concluída | S24: 28/08/2022 | T24: 28/07/2022 14:29 | U24: 27/07/2022 21:00 | V24: 31/07/2022 21:00 | W24: 31/07/2022 21:00 | X24: =W24*1 -> 44773.875 | Y24: MIGRADO_ZOHO | Z24: Pesquisa de Bens | AA24: BANCO DO BRASIL (SGL_NAME) | AB24: Rua Marino Paterlini | AC24: Presidente Medici | AD24: 0 | AE24: 0 | AF24: 395 | AG24: m2 | AH24: T1 | AI24: Remota | AJ24: Concluido | AL24: 28/07/2022 | AM24: 27/07/2022 21:00 | AN24: 27/07/2022 21:00 | AO24: 27/07/2022 21:00 | AP24: SIGLOCAL | AQ24: Avaliado | AS24: Normal | AT24: 28/08/2022 | AU24: 27/07/2022 21:00 | AV24: 31/07/2022 21:00 | AW24: 31/07/2022 21:00 | AX24: ANDRE MAGIORE | AY24: Avaliado | BB24: 28/08/2022 | BC24: 31/07/2022 21:00 | BD24: 31/07/2022 21:00 | BE24: 31/07/2022 21:00 | BF24: ANDERSON SCARPINO | BH24: FALSE | BK24: FALSE
B25: 15292 | C25: COZAC | D25: 6549 | E25: 0 | F25: 0 | H25: Imóvel Urbano | I25: Casa Residencial | J25: Ribeirão Preto | K25: SP | L25: Localizado | M25: Nível 2 | N25: Validação Avaliação Urbano | O25: ANA CLARA | P25: Gestão BNDU | Q25: ANDERSON SCARPINO | R25: Concluída | S25: 17/07/2025 | T25: 05/06/2025 17:12 | U25: 17/07/2025 16:34 | V25: 17/07/2025 17:04 | W25: 17/07/2025 17:13 | X25: =W25*1 -> 45855.717 | Z25: Pesquisa de Bens | AA25: BANCO DO BRASIL (SGL_NAME) | AB25: Rua Olavo Bilac | AC25: Jardim Sumare | AD25: 192.54 | AF25: 757 | AG25: m2 | AH25: T1 | AI25: Remota | AJ25: Concluido | AL25: 04/04/2023 | AM25: 28/03/2023 17:53 | AN25: 29/03/2023 09:04 | AO25: 04/04/2023 11:32 | AP25: SIGLOCAL ACESSO | AT25: 18/07/2025 | AU25: 17/07/2025 16:34 | AV25: 17/07/2025 14:35 | AW25: 17/07/2025 16:34 | AX25: Victor Libarino | BB25: 17/07/2025 | BC25: 17/07/2025 16:34 | BD25: 17/07/2025 17:04 | BE25: 17/07/2025 17:13 | BF25: ANDERSON SCARPINO | BG25: TRUE | BH25: FALSE | BK25: FALSE
B26: 15292 | C26: COZAC | D26: 6549 | E26: 1158000 | F26: 822000 | H26: Imóvel Urbano | I26: Casa Residencial | J26: Ribeirão Preto | K26: SP | L26: Localizado | M26: Nível 2 | N26: Validação Avaliação Urbano | O26: THIAGO MACHADO | P26: GESTÃO PORTFÓLIO | Q26: ANDERSON SCARPINO | R26: Concluída | S26: 10/07/2023 | T26: 06/06/2023 16:39 | U26: 10/07/2023 17:25 | V26: 10/07/2023 17:27 | W26: 10/07/2023 17:28 | X26: =W26*1 -> 45117.728 | Z26: Acordo | AA26: BANCO DO BRASIL (SGL_NAME) | AB26: Rua Olavo Bilac | AC26: Jardim Sumare | AD26: 185 | AF26: 757 | AG26: m2 | AH26: T1 | AI26: Remota | AJ26: Concluido | AL26: 04/04/2023 | AM26: 28/03/2023 17:53 | AN26: 29/03/2023 09:04 | AO26: 04/04/2023 11:32 | AP26: SIGLOCAL ACESSO | AT26: 10/07/2023 | AU26: 10/07/2023 17:25 | AV26: 10/07/2023 17:10 | AW26: 10/07/2023 17:25 | AX26: RAPHAEL PARENTE | BB26: 10/07/2023 | BC26: 10/07/2023 17:25 | BD26: 10/07/2023 17:27 | BE26: 10/07/2023 17:28 | BF26: ANDERSON SCARPINO | BG26: TRUE | BH26: FALSE | BK26: FALSE
B27: 15292 | C27: COZAC | D27: 6549 | E27: 1233597.7 | F27: 900526.33 | H27: Imóvel Urbano | I27: Casa Residencial | J27: Ribeirão Preto | K27: SP | L27: Localizado | M27: Nível 1 | N27: Validação Avaliação Urbano | O27: NATHALIA DIAS | P27: Investigação | Q27: MATHEUS NAVARRO | R27: Concluída | S27: 20/04/2023 | T27: 28/03/2023 17:53 | U27: 07/04/2023 18:00 | V27: 14/04/2023 10:36 | W27: 19/04/2023 18:27 | X27: =W27*1 -> 45035.769 | Z27: Pesquisa de Bens | AA27: BANCO DO BRASIL (SGL_NAME) | AB27: Rua Olavo Bilac | AC27: Jardim Sumare | AD27: 170 | AF27: 757 | AG27: m2 | AH27: T1 | AI27: Remota | AJ27: Concluido | AL27: 04/04/2023 | AM27: 28/03/2023 17:53 | AN27: 29/03/2023 09:04 | AO27: 04/04/2023 11:32 | AP27: SIGLOCAL ACESSO | AQ27: Avaliado | AR27: Concluido | AS27: Normal | AT27: 13/04/2023 | AU27: 07/04/2023 18:00 | AV27: 06/04/2023 08:20 | AW27: 07/04/2023 18:00 | AX27: RAIZA GONÇALVES | AY27: Avaliado | AZ27: Concluido | BA27: Normal | BB27: 20/04/2023 | BC27: 07/04/2023 18:00 | BD27: 14/04/2023 10:36 | BE27: 19/04/2023 18:27 | BF27: MATHEUS NAVARRO | BH27: FALSE | BK27: FALSE
